Workbook

Sheet МЕНЮ
A2: № п/п | B2: Кава-брейк 10:40 - 11:15 | C2: Вихід на стіл, порція/вага, гр. | D2: Кіл-сть порцій | E2: Ціна, грн | F2: Сума, грн | G2: Вихід грам на особу
B3: Меню із розрахунку на 40 осіб
B4: Холодні закуск
A5: 1 | B5: Брускета з іспанським хамоном та грушою | C5: 45 | D5: 40 | E5: 57 | F5: =E5*D5 -> 2280 | G5: 45 | H5: =G5*D5/40 -> 45
A6: 2 | B6: Валован з шампіньйонами та вершковим сиром | C6: 35 | D6: 40 | E6: 45 | F6: =E6*D6 -> 1800 | G6: 35 | H6: =G6*D6/40 -> 35
A7: 3 | B7: Кіш-лорен з куркою та грибами у тарталетці | C7: 45 | D7: 40 | E7: 57 | F7: =E7*D7 -> 2280 | G7: 35 | H7: =G7*D7/40 -> 35
B8: Десерти
A9: 1 | B9: Еклери зі згущеним молоком | C9: 35 | D9: 40 | E9: 26 | F9: =E9*D9 -> 1040 | G9: 35 | H9: =G9*D9/40 -> 35
B10: Напої
A11: 1 | B11: Кава натуральна з вершками | C11: 50 - 150 | D11: 30 | E11: 51 | F11: =E11*D11 -> 1530
A12: 2 | B12: Чай пакетований в асортименті | C12: 200 | D12: 10 | E12: 25 | F12: =E12*D12 -> 250
A13: 3 | B13: Лимон | C13: 10 | D13: 10 | E13: 8 | F13: =E13*D13 -> 80
A14: 4 | B14: VODA ua газована | C14: 500 | D14: 40 | E14: 32 | F14: =E14*D14 -> 1280
A15: 5 | B15: VODA ua негазована | C15: 500 | D15: 40 | E15: 32 | F15: =E15*D15 -> 1280
H16: Меню
E17: Всього: | F17: =SUM(F5:F15) -> 11820 | H17: =SUM(H5:H9) -> 150 | I17: грм/люд
E19: Знижка 10%: | F19: =F17*10% -> 1182 | H19: =F21/40 -> 265.95 | I19: грн/люд
E21: Разом до сплати: | F21: =F17-F19 -> 10638
B27: Обладнання та сервіс
A28: 1 | B28: Кава-брейк | F28: =F21 -> 10638
A29: 2 | B29: Посуд, текстиль, меблі, обладнання | F29: =ОБЛАДНАННЯ!G331 -> 1378
A30: 3 | B30: Коктейльні столи | D30: 5 | E30: 350 | F30: =E30*D30 -> 1750
A31: 4 | B31: Сервіс - обслуговування, офіціанти, кухар, тех.персонал, адміністратор | F31: =SUM('КОМЕРЦІЙНА ПРОПОЗИЦІЯ'!B20:B23) -> 4800
A32: 5 | B32: Транспорт з урахуванням доставки обладнання та персоналу | F32: ='КОМЕРЦІЙНА ПРОПОЗИЦІЯ'!B25 -> 2500
A33: 6 | B33: Всього до сплати | F33: =SUM(F28:F32) -> 21066
F35: =F39/40 -> 558.249 | G35: грн/люд
E37: До оплати через ФОП 3-я категорія (+6%) | F37: =F33*6% -> 1263.96
E39: Разом до оплати: | F39: =F33+F37 -> 22329.96
B42: Зверніть увагу:
B43: У файлі, що складається з трьох вкладок,
B44: я Вам запропонував меню, необхідне обладнання та
B45: обслуговування заходу!
B47: Запропоноване меню можемо коригувати за
B48: асортиментом страв, кількості порцій та бюджету!!
B50: Умови бронювання заходу:
A52: 1. | B52: Дата бронюється після передоплати за захід
A53: 2. | B53: Передоплата сплачується в розмірі 50%, залишок сплачується в день заходу.
A54: 3. | B54: Передоплата повертається у розмірі 30% при повідомленні про відміну заходу за 5 днів до броньованої дати
A55: 4. | B55: Передоплата не повертається при повідомленні про відміну заходу за 3 дні до броньованої дати
A56: 5. | B56: Оплата можлива готівкою, переказ на карту або оплатою на рахунок ФОП 3-ї групи.
...

Sheet ОБЛАДНАННЯ
A1: Розкрути свою ідею dzyga-catering.com.ua catering.dzyga@gmail.com | E1: (093) 423-22-90; (050) 423-22-90; (096) 423-22-90
A2: № | B2: Найменування | C2: Кількість на складі | D2: Ціна прокату за шт/грн. | E2: Ціна втрати шт/грн. | F2: Необхідна кількість | G2: Вартість
B3: СКЛО | F3: 1 | H3: =SUM(G4:G27) -> 0
A4: 1 | B4: Келих для вина Black 350 мл Domino | C4: 26 | D4: 16 | E4: 130 | G4: =SUM(D4*F4) -> 0
A5: 2 | B5: Келих для вина Black 250 мл Domino | C5: 42 | D5: 16 | E5: 120 | G5: =SUM(D5*F5) -> 0
A6: 3 | B6: Келих для шампанського Фужер Black 170 мл Domino | C6: 28 | D6: 16 | E6: 110 | G6: =SUM(D6*F6) -> 0
A7: 4 | B7: Келих для коньяку Black 410 мл Domino | C7: 51 | D7: 16 | E7: 105 | G7: =SUM(D7*F7) -> 0
A8: 5 | B8: Чарка на ніжці Black 65 мл Domino | C8: 47 | D8: 10 | E8: 75 | G8: =SUM(D8*F8) -> 0
A9: 6 | B9: Келих для вина 350 мл Signature | C9: 350 | D9: 15 | E9: 80 | G9: =SUM(D9*F9) -> 0
A10: 7 | B10: Келих для вина 250 мл Signature | C10: 350 | D10: 15 | E10: 75 | G10: =SUM(D10*F10) -> 0
A11: 8 | B11: Келих для шампанського Фужер 170 мл Signature | C11: 700 | D11: 15 | E11: 75 | G11: =SUM(D11*F11) -> 0
A12: 9 | B12: Келих для коньяку 250 мл Signature | C12: 60 | D12: 10 | E12: 60 | G12: =SUM(D12*F12) -> 0
A13: 10 | B13: Чарка на ніжці 65 мл Signature | C13: 75 | D13: 9 | E13: 60 | G13: =SUM(D13*F13) -> 0
A14: 11 | B14: Салатник 160 мл Vasics | C14: 700 | D14: 18 | E14: 100 | G14: =SUM(D14*F14) -> 0
A15: 12 | B15: Стопка шот Бостон 60 мл | C15: 120 | D15: 9 | E15: 20 | G15: =SUM(D15*F15) -> 0
... A27: 24 | B27: Графін для горілки та коньяку 0.5 л Арка | C27: 12 | D27: 20 | E27: 75 | G27: =SUM(D27*F27) -> 0
B28: ФАРФОР | F28: 1 | H28: =SUM(G30:G43) -> 880
A29: № | B29: Найменування | D29: Ціна прокату за шт/грн. | E29: Ціна втрати шт/грн. | F29: Необхідна кількість | G29: Вартість
A30: 1 | B30: Чашка чайна та блюдце 220 мл Wilmax | C30: 197 | D30: 12 | E30: 200 | F30: 40 | G30: =D30*F30 -> 480
A31: 2 | B31: Чашка кавова та блюдце 140 мл Wilmax | C31: 20 | D31: 12 | E31: 150 | G31: =D31*F31 -> 0
A32: 3 | B32: Молочник 200 мл Wilmax | C32: 9 | D32: 10 | E32: 140 | G32: =D32*F32 -> 0
A33: 4 | B33: Підставка для порційного цукру 9х6,5х4,5 см Wilmax | C33: 3 | D33: 8 | E33: 120 | G33: =D33*F33 -> 0
A34: 5 | B34: Чайник заварювальний 700 мл Wilmax | C34: 1 | D34: 50 | E34: 450 | G34: =D34*F34 -> 0
A35: 6 | B35: Цукорниця 540 мл Wilmax | C35: 1 | D35: 10 | E35: 290 | G35: =D35*F35 -> 0
A36: 7 | B36: Набір сіль і перець 4 пр. Wilmax | C36: 57 | D36: 30 | E36: 240 | G36: =D36*F36 -> 0
A37: 8 | B37: Підставка для серветок 11х8 cм Wilmax | C37: 53 | D37: 15 | E37: 150 | G37: =D37*F37 -> 0
A38: 9 | B38: Тарілка пиріжкова квадратна 16,5 см Wilmax | C38: 75 | D38: 10 | E38: 130 | F38: 40 | G38: =D38*F38 -> 400
A39: 10 | B39: Тарілка обідня квадратна 25,5 см Wilmax | C39: 24 | D39: 15 | E39: 280 | G39: =D39*F39 -> 0
A40: 11 | B40: Тарілка десертна кругла 18 см Wilmax | C40: 142 | D40: 10 | E40: 110 | G40: =D40*F40 -> 0
A41: 12 | B41: Тарілка закусочна кругла 23 см Wilmax | C41: 130 | D41: 12 | E41: 190 | G41: =D41*F41 -> 0
A42: 13 | B42: Тарілка обідня кругла 25,5 см Wilmax | C42: 106 | D42: 15 | E42: 260 | G42: =D42*F42 -> 0
A43: 14 | B43: Бульйонниця 300 мл Wilmax | C43: 114 | D43: 10 | E43: 180 | G43: =D43*F43 -> 0
B44: КЕРАМОСКЛО | F44: 1 | H44: =SUM(G46:G50) -> 0
A45: № | B45: Найменування | D45: Ціна прокату за шт/грн. | E45: Ціна втрати шт/грн. | F45: Необхідна кількість | G45: Вартість
A46: 1 | B46: Тарілка закусочна white 190 мм Carine | C46: 53 | D46: 10 | E46: 80 | G46: =D46*F46 -> 0
A47: 2 | B47: Тарілка закусочна black 190 мм Carine | C47: 57 | D47: 10 | E47: 80 | G47: =D47*F47 -> 0
A48: 3 | B48: Тарілка закусочна зелена 21 см Ipec | C48: 47 | D48: 10 | E48: 120 | G48: =D48*F48 -> 0
A49: 4 | B49: Тарілка глибока зелена 24 см Ipec | C49: 79 | D49: 12 | E49: 80 | G49: =D49*F49 -> 0
A50: 5 | B50: Супник зелений 16 см Ipec | C50: 80 | D50: 8 | E50: 60 | G50: =D50*F50 -> 0
B51: СТОЛОВІ ПРИЛАДИ | F51: 1 | H51: =SUM(G53:G80) -> 400
...

Sheet КОМЕРЦІЙНА ПРОПОЗИЦІЯ
A2: Назва проекту (привід) | B2: Кейтеринг
A3: Замовник: | B3: Аркадій
A4: телефон: | B4: 050 575 29 52
A5: email:
A6: Координатор: | B6: Роман
A7: Координатор тел.: | B7: 068 423 22 90
A8: Дата проведення: | B8: 45415
A9: Місце проведення: | B9: вул. Вишгородська 21
A10: Час: | B10: 10:40 - 11:15
A11: Кількість осіб: | B11: 40
A14: Кухня
A15: Кава-брейк | B15: =МЕНЮ!F21 -> 10638
A16: Оренда обладнання
A17: Оренда обладнання | B17: =ОБЛАДНАННЯ!G331 -> 1378
A18: Коктейльні столи 5шт | B18: =МЕНЮ!F30 -> 1750
A19: Обслуговування
A20: Менеджер обслуговування | B20: 1000
A21: Обслуговування офіціантами | B21: 1800 | C21: 2 офіціанти
A22: Кухар для розкладання страв та обслуговування заходу
A23: Тех. Персонал | B23: 2000 | C23: 2 тех.персонала
A24: Транспортні витрати
A25: Транспортні витрати (для доставки обладнання та персоналу) | B25: 2500
A26: Сума до оплати
A27: Разом сума до оплати | B27: =SUM(B15:B26) -> 21066
A29: Всього на персону: | B29: =SUM(B15:B25) -> 21066
A31: До оплати через ФОП 3-я категорія (+6%) | B31: =B27*6% -> 1263.96
A33: Разом до оплати: | B33: =B27+B31 -> 22329.96
