Workbook

Sheet калькуляции
B1: Вихід, грам | C1: Назва | D1: Продукти | E1: Вага у грамах
A2: Холодні рибні закуски | G2: point
B3: 150 | C3: Ніжне філе слабосоленого лосося з олію та кріпом | E3: =SUM(E4:E8) -> 165 | G3: point
A4: =E4*A3 -> 0 | D4: Філе лосося | E4: 120 | F4: =SUMIF('список продуктов'!$A$8:$A$917,"="&D4,'список продуктов'!$C$8:$C$917) -> 1
A5: =E5*A3 -> 0 | D5: Масло вершкове | E5: 10 | F5: =SUMIF('список продуктов'!$A$8:$A$917,"="&D5,'список продуктов'!$C$8:$C$917) -> 1
A6: =E6*A3 -> 0 | D6: Кріп свіжий | E6: 10 | F6: =SUMIF('список продуктов'!$A$8:$A$917,"="&D6,'список продуктов'!$C$8:$C$917) -> 1
A7: =E7*A3 -> 0 | D7: Салат Лолло Росса | E7: 10 | F7: =SUMIF('список продуктов'!$A$8:$A$917,"="&D7,'список продуктов'!$C$8:$C$917) -> 1
A8: =E8*A3 -> 0 | D8: Лимон | E8: 15 | F8: =SUMIF('список продуктов'!$A$8:$A$917,"="&D8,'список продуктов'!$C$8:$C$917) -> 1
B9: 150 | C9: Рибне плато: слабосолена сьомга, копчена масляна риба, палтус х/к, Зелень | E9: =SUM(E10:E14) -> 170 | G9: point
A10: =E10*A9 -> 0 | D10: Філе лосося | E10: 50 | F10: =SUMIF('список продуктов'!$A$8:$A$917,"="&D10,'список продуктов'!$C$8:$C$917) -> 1
A11: =E11*A9 -> 0 | D11: Масляна риба х/к | E11: 50 | F11: =SUMIF('список продуктов'!$A$8:$A$917,"="&D11,'список продуктов'!$C$8:$C$917) -> 1
A12: =E12*A9 -> 0 | D12: Палтус х/к | E12: 50 | F12: =SUMIF('список продуктов'!$A$8:$A$917,"="&D12,'список продуктов'!$C$8:$C$917) -> 1
A13: =E13*A9 -> 0 | D13: Салат Лолло Росса | E13: 10 | F13: =SUMIF('список продуктов'!$A$8:$A$917,"="&D13,'список продуктов'!$C$8:$C$917) -> 1
A14: =E14*A9 -> 0 | D14: Кріп свіжий | E14: 10 | F14: =SUMIF('список продуктов'!$A$8:$A$917,"="&D14,'список продуктов'!$C$8:$C$917) -> 1
B15: 210 | C15: Асорті "Рибна симфонія": філе лосося с/с, масляна с/с, млинці з лососевою ікрою | E15: =SUM(E16:E29) -> 291.25 | G15: point
A16: =E16*A15 -> 0 | D16: Філе лосося | E16: 60 | F16: =SUMIF('список продуктов'!$A$8:$A$917,"="&D16,'список продуктов'!$C$8:$C$917) -> 1
A17: =E17*A15 -> 0 | D17: Масло вершкове | E17: 40 | F17: =SUMIF('список продуктов'!$A$8:$A$917,"="&D17,'список продуктов'!$C$8:$C$917) -> 1
A18: =E18*A15 -> 0 | D18: Кріп свіжий | E18: 10 | F18: =SUMIF('список продуктов'!$A$8:$A$917,"="&D18,'список продуктов'!$C$8:$C$917) -> 1
A19: =E19*A15 -> 0 | D19: Салат Лолло Росса | E19: 10 | F19: =SUMIF('список продуктов'!$A$8:$A$917,"="&D19,'список продуктов'!$C$8:$C$917) -> 1
A20: =E20*A15 -> 0 | D20: Лимон | E20: 15 | F20: =SUMIF('список продуктов'!$A$8:$A$917,"="&D20,'список продуктов'!$C$8:$C$917) -> 1
A21: =E21*A15 -> 0 | D21: Масляна риба х/к | E21: 60 | F21: =SUMIF('список продуктов'!$A$8:$A$917,"="&D21,'список продуктов'!$C$8:$C$917) -> 1
A22: =E22*A15 -> 0 | D22: Ікра лососева | E22: 10 | F22: =SUMIF('список продуктов'!$A$8:$A$917,"="&D22,'список продуктов'!$C$8:$C$917) -> 1
C23: Млинець жарений(1шт):
A24: =E24*A15 -> 0 | D24: Борошно | E24: 20.5 | F24: =SUMIF('список продуктов'!$A$8:$A$917,"="&D24,'список продуктов'!$C$8:$C$917) -> 1
A25: =E25*A15 -> 0 | D25: Молоко | E25: 52 | F25: =SUMIF('список продуктов'!$A$8:$A$917,"="&D25,'список продуктов'!$C$8:$C$917) -> 0
A26: =E26*A15 -> 0 | D26: Яйце куряче | E26: 8 | F26: =SUMIF('список продуктов'!$A$8:$A$917,"="&D26,'список продуктов'!$C$8:$C$917) -> 1
A27: =E27*A15 -> 0 | D27: Сіль | E27: 0.5 | F27: =SUMIF('список продуктов'!$A$8:$A$917,"="&D27,'список продуктов'!$C$8:$C$917) -> 1
A28: =E28*A15 -> 0 | D28: Цукор | E28: 1.75 | F28: =SUMIF('список продуктов'!$A$8:$A$917,"="&D28,'список продуктов'!$C$8:$C$917) -> 1
A29: =E29*A15 -> 0 | D29: Олія соняшникова | E29: 3.5 | F29: =SUMIF('список продуктов'!$A$8:$A$917,"="&D29,'список продуктов'!$C$8:$C$917) -> 1
B31: 6000 | C31: Морські делікатеси по-царськи: вугор, раки, омари, фаршировані кальмари, мідії | E31: =SUM(E32:E40) -> 8400 | G31: point
A32: =E32*A31 -> 0 | D32: Вугор х/к | E32: 1500 | F32: =SUMIF('список продуктов'!$A$8:$A$917,"="&D32,'список продуктов'!$C$8:$C$917) -> 1
A33: =E33*A31 -> 0 | D33: Омар | E33: 1500 | F33: =SUMIF('список продуктов'!$A$8:$A$917,"="&D33,'список продуктов'!$C$8:$C$917) -> 1
A34: =E34*A31 -> 0 | D34: Раки | E34: 1500 | F34: =SUMIF('список продуктов'!$A$8:$A$917,"="&D34,'список продуктов'!$C$8:$C$917) -> 1
A35: =E35*A31 -> 0 | D35: Тушка кальмара очищена с/м | E35: 1500 | F35: =SUMIF('список продуктов'!$A$8:$A$917,"="&D35,'список продуктов'!$C$8:$C$917) -> 1
A36: =E36*A31 -> 0 | D36: Мідії в панцирі | E36: 1500 | F36: =SUMIF('список продуктов'!$A$8:$A$917,"="&D36,'список продуктов'!$C$8:$C$917) -> 1
A37: =E37*A31 -> 0 | D37: Лимон | E37: 500 | F37: =SUMIF('список продуктов'!$A$8:$A$917,"="&D37,'список продуктов'!$C$8:$C$917) -> 1
A38: =E38*A31 -> 0 | D38: Оливки без кісточки | E38: 150 | F38: =SUMIF('список продуктов'!$A$8:$A$917,"="&D38,'список продуктов'!$C$8:$C$917) -> 1
A39: =E39*A31 -> 0 | D39: Маслини без кісточки | E39: 150 | F39: =SUMIF('список продуктов'!$A$8:$A$917,"="&D39,'список продуктов'!$C$8:$C$917) -> 1
A40: =E40*A31 -> 0 | D40: Салат Лоло Біонда | E40: 100 | F40: =SUMIF('список продуктов'!$A$8:$A$917,"="&D40,'список продуктов'!$C$8:$C$917) -> 1
B41: 35 | C41: Французькі профітролі з лососевою ікрою, вершковим сиром та лимончиком | E41: =SUM(E42:E46)+15 -> 39 | G41: point
...

Sheet список продуктов
A2: Позначення | B2: Закупка в грамах
A6: РИБНИЙ
A7: РИБА
A8: Лосось свіжий (тушка) | B8: =калькуляции!A4525+калькуляции!A4664 -> 0 | C8: 1
A9: Риба-меч | B9: =калькуляции!A4153 -> 0 | C9: 1
A10: Сьомга стейк | B10: =калькуляции!A4295+калькуляции!A4312+калькуляции!A4348+калькуляции!A4376+калькуляции!A4390 -> 0 | C10: 1
A11: Стейк амура | B11: =калькуляции!A4590 -> 0 | C11: 1
A12: Стейк форель | B12: =калькуляции!A4645 -> 0 | C12: 1
A13: Філе пангасіуса | B13: =калькуляции!A4324+калькуляции!A11764+калькуляции!A10607+калькуляции!A12159+калькуляции!A11843 -> 0 | C13: 1
A14: Філе судака | B14: =калькуляции!A56+калькуляции!A166+калькуляции!A240+калькуляции!A4100+калькуляции!A4128+калькуляции!A4165+калькуляции!A4274+калькуляции!A4447+калькуляции!A4534+калькуляции!A4602+калькуляции!A7696 -> 0 | C14: 1
A15: Філе сома | B15: =калькуляции!A3979+калькуляции!A4014+калькуляции!A4260+калькуляции!A4334+калькуляции!A4401+калькуляции!A4610+калькуляции!A4629 -> 0 | C15: 1
A16: Філе тріски | B16: =калькуляции!A4434 -> 0 | C16: 1
A17: Філе тунця | B17: =калькуляции!A4543+калькуляции!A10297+калькуляции!A5890+калькуляции!A12938 -> 0 | C17: 1
A18: Філе лосося | B18: =калькуляции!A167+калькуляции!A185+калькуляции!A239+калькуляции!A5367+калькуляции!A1864+калькуляции!A3951+калькуляции!A3965+калькуляции!A3990+калькуляции!A4179+калькуляции!A4364+калькуляции!A4461+калькуляции!A4611+калькуляции!A4621+калькуляции!A7508+калькуляции!A8049+калькуляции!A4323+калькуляции!A1884+калькуляции!A1904+калькуляции!A5831+калькуляции!A10096+калькуляции!A10005+калькуляции!A10290+калькуляции!A5880+калькуляции!A12972+калькуляции!A5955+калькуляции!A12931+калькуляции!A4973+калькуляции!A11754+калькуляции!A11735+калькуляции!A11752+калькуляции!A16+калькуляции!A4966+калькуляции!A5307+калькуляции!A5384+калькуляции!A1712+калькуляции!A10212+калькуляции!A4+калькуляции!A13021+калькуляции!A10140+калькуляции!A10+калькуляции!A118+калькуляции!A1061+калькуляции!A1104+калькуляции!A5231+калькуляции!A5278+калькуляции!A5437+калькуляции!A6969+калькуляции!A1584+калькуляции!A1593+калькуляции!A7999+калькуляции!A109+калькуляции!A6238+калькуляции!A2007+калькуляции!A5454+калькуляции!A6216+калькуляции!A7077+калькуляции!A11827+калькуляции!A11841+калькуляции!A11865+калькуляции!A10842+калькуляции!A11029+калькуляции!A11542+калькуляции!A11318+калькуляции!A6426+калькуляции!A6450+калькуляции!A6473+калькуляции!A11217+калькуляции!A5130+калькуляции!A5145+калькуляции!A769+калькуляции!A11481+калькуляции!A738+калькуляции!A9948+калькуляции!A9927+калькуляции!A4+калькуляции!A7114+калькуляции!A1679 -> 0 | C18: 1
A19: Філе осетрини | B19: =калькуляции!A176+калькуляции!A4002+калькуляции!A4240+калькуляции!A4250 -> 0 | C19: 1
A20: Філе окуня | B20: =калькуляции!A3964+калькуляции!A4221 -> 0 | C20: 1
A21: Філе хека | B21: =калькуляции!A1420+калькуляции!A10621+калькуляции!A12381+калькуляции!A12662 -> 0 | C21: 1
A22: Філе мінтая | B22: =калькуляции!A4114+калькуляции!A4139+калькуляции!A10635 -> 0 | C22: 1
A23: Філе риби оптимальне | B23: =калькуляции!A8991+калькуляции!A8998+калькуляции!A9006 -> 0 | C23: 1
A24: Філе телапії | B24: =калькуляции!A12550 -> 0 | C24: 1
A25: Форель райдужна (річкова) | B25: =калькуляции!A1462+калькуляции!A4501 -> 0 | C25: 1
A26: Анчоуси філе | B26: =калькуляции!A3842 -> 0 | C26: 1
A27: Дорадо | B27: =калькуляции!A4513+калькуляции!A4655 -> 0 | C27: 1
A28: Сібас | B28: =калькуляции!A4475+калькуляции!A4488 -> 0 | C28: 1
A29: Скумбрія | B29: =калькуляции!A4194+калькуляции!A12009+калькуляции!A12295+калькуляции!A13305+калькуляции!A13425+калькуляции!A4635 -> 0 | C29: 1
A30: Карп | B30: =калькуляции!A93+калькуляции!A7684+калькуляции!A12357 -> 0 | C30: 1
A31: МОРЕПРОДУКТИ
A32: Креветки королівські в панцирі | B32: =калькуляции!A4065 -> 0 | C32: 1
A33: Креветки коктейльні | B33: =калькуляции!A73+калькуляции!A227+калькуляции!A6676+калькуляции!A1531+калькуляции!A1780+калькуляции!A4026+калькуляции!A4241+калькуляции!A4584+калькуляции!A4833+калькуляции!A7555+калькуляции!A7818+калькуляции!A1945+калькуляции!A5963+калькуляции!A1971 -> 0 | C33: 1
A34: Креветка 16/20 | B34: =калькуляции!A2059+калькуляции!A4672+калькуляции!A11548+калькуляции!A11331+калькуляции!A6456+калькуляции!A6484+калькуляции!A4690+калькуляции!A4700+калькуляции!A5752+калькуляции!A5339+калькуляции!A6694+калькуляции!A1628+калькуляции!A9990+калькуляции!A10019+калькуляции!A10283+калькуляции!A5856+калькуляции!A12918+калькуляции!A6289+калькуляции!A10384+калькуляции!A5511+калькуляции!A6162+калькуляции!A5678 -> 0 | C34: 1
A35: Гребінець морський | B35: =калькуляции!A1733+калькуляции!A4206+калькуляции!A4486+калькуляции!A4554 -> 0 | C35: 1
A36: Тушка кальмара очищена с/м | B36: =калькуляции!A35+калькуляции!A72+калькуляции!A4557+калькуляции!A7507 -> 0 | C36: 1
A37: Креветка тигрова | B37: =калькуляции!A156+калькуляции!A206+калькуляции!A6757+калькуляции!A13042+калькуляции!A13066+калькуляции!A13083+калькуляции!A1480+калькуляции!A1607+калькуляции!A1731+калькуляции!A4041+калькуляции!A4053+калькуляции!A4207+калькуляции!A4536+калькуляции!A4556+калькуляции!A4567+калькуляции!A7506+калькуляции!A10831 -> 0 | C37: 1
A38: Мідії | B38: =калькуляции!A1530+калькуляции!A1732+калькуляции!A4091+калькуляции!A7606+калькуляции!A5964+калькуляции!A6308 -> 0 | C38: 1
A39: Мідії в панцирі | B39: =калькуляции!A36+калькуляции!A4555+калькуляции!A7505 -> 0 | C39: 1
A40: Устриця, 12 шт. | B40: =калькуляции!A261 -> 0 | C40: 1
A41: М'ясо краба (ракові шийки) | B41: =калькуляции!A996+калькуляции!A5183+калькуляции!A6610+калькуляции!A6699 -> 0 | C41: 1
A42: Омар | B42: =калькуляции!A33 -> 0 | C42: 1
A43: Раки | B43: =калькуляции!A34+калькуляции!A4412 -> 0 | C43: 1
A44: ГОТОВІ РИБНІ ВИРОБИ
...
